Workbook

Sheet 00_Metodologia
A1: Matriz de Aderência à IN GABSEC/SENAPPEN/MJSP nº 75/2026
A2: Modelo de monitoramento ONASP. Regra metodológica: cada pergunta do diagnóstico integra uma única dimensão ou, quando aplicável, exclusivamente o bloco de bônus.
A4: Dimensão | B4: Peso-base | C4: Perguntas do diagnóstico | D4: Quantidade de perguntas | E4: Função | F4: Regra geral | G4: Fundamento predominante | H4: Regra de unicidade | I4: Observação | J4: Bônus? | K4: Aba
A5: 01 — Institucionalização | B5: 15 | C5: M1-11 | D5: 1 | E5: Instituição formal e porta de entrada | F5: Sim = 15; Não/Sem evidência = 0 | G5: Art. 6º, caput | H5: M1-11 só aparece nesta dimensão. | I5: Também funciona como requisito de entrada. | J5: Não | K5: 01_Institucionalização
A6: 02 — Autonomia técnica e funcional | B6: 15 | C6: M3-56; M3-57; M1-12; M4-67; M4-68 | D6: 5 | E6: Autonomia institucional e condições de atuação | F6: Atende = integral; Parcial = 50%; demais = 0 | G6: Arts. 4º, I; 6º; 8º; 10; 13 | H6: Nenhuma pergunta é reutilizada em outra dimensão. | I6: 5 perguntas × 3 pontos. | J6: Não | K6: 02_Autonomia
A7: 03 — Imparcialidade, sigilo e proteção | B7: 15 | C7: M4-69; M3-63 | D7: 2 | E7: Proteção de denúncias sensíveis e compromisso de sigilo | F7: Atende = integral; Parcial = 50%; demais = 0 | G7: Arts. 4º, II; 9º; 10 | H7: M4-66 e M2-37 foram retiradas desta dimensão e permanecem em Integração tecnológica. | I7: Pesos: 8 + 7. | J7: Não | K7: 03_Imparcialidade
A8: 04 — Acessibilidade e atendimento humanizado | B8: 15 | C8: M2-41; M2-43; M2-47; M2-16; M1-13; M4-64 | D8: 6 | E8: Canais, espaço físico e alcance dos públicos | F8: Atende = integral; Parcial = 50%; demais = 0 | G8: Arts. 4º, III; 7º; 10 | H8: M2-45 foi retirada desta dimensão e permanece em Integração tecnológica. | I8: Pesos: 2+2+2+3+3+3. | J8: Não | K8: 04_Acessibilidade
A9: 05 — Transparência e publicidade | B9: 15 | C9: M2-35; M4-71 | D9: 2 | E9: Visibilidade e publicidade das ações | F9: Atende = integral; Parcial = 50%; demais = 0 | G9: Arts. 4º, IV; 7º; 10; 12 | H9: M1-12 foi retirada desta dimensão e permanece em Autonomia. | I9: Pesos: 5 + 10. | J9: Não | K9: 05_Transparência
A10: 06 — Integração tecnológica | B10: 25 | C10: M2-45; M4-66; M2-37; M2-17; M2-19; M2-21; M2-27 | D10: 7 | E10: Canal/sistema, protocolo, segurança e equipamentos | F10: Atende = integral; Parcial = 50%; demais = 0 | G10: Arts. 4º, V; 7º; 11; 13 | H10: M4-67 foi retirada desta dimensão e permanece em Autonomia. | I10: Pesos: 5+5+5+4+2+2+2. | J10: Não | K10: 06_Integração Tec
A11: TOTAL BASE | B11: 100 | C11: — | D11: 23 | E11: Nota-base | F11: Soma das seis dimensões | G11: Metodologia ONASP | H11: Nenhuma pergunta-base é repetida. | I11: Nota-base máxima = 100. | J11: — | K11: 08_Resumo
A12: 07 — Maturidade / bônus | B12: 10 | C12: M2-46; M0-08; M3-60; M3-58; M2-50; M2-49; M2-36 | D12: 7 | E12: Características adicionais de maturidade | F12: Sim = bônus integral; demais = 0 | G12: Arts. 4º; 6º; 7º; 8º; 9º | H12: Nenhuma pergunta do bônus aparece na pontuação-base. | I12: Aplicado somente até completar 100. | J12: Sim | K12: 07_Maturidade
A14: Tratamento da base: Espírito Santo permanece com duas unidades de avaliação (Polícia Penal e SEJUS/ES). RO e SC permanecem com as respostas mais recentes já consolidadas na planilha de origem. Todas as colunas de evidências/observações mantêm a referência Doc. SEI 37070578.

Sheet 01_Institucionalização
A1: 01 — Institucionalização
A2: Peso: 15 pontos. A existência de ato normativo específico também funciona como requisito de entrada para a classificação de aderência.
A4: Identificação | C4: Item 1 — Instituição formal da Ouvidoria de Serviços Penais | G4: Resultado
A5: UF | B5: Unidade Federativa | C5: M1-11 — Existe ato normativo específico que cria a Ouvidoria de Serviços Penais ou núcleo especializado? | D5: Resposta do diagnóstico | E5: Fundamentação na IN nº 75/2026 | F5: 15 pts | G5: Pontuação /15 | H5: Situação institucional | I5: Evidências / observações
A6: Como aplicar / resposta / fundamento → | C6: 15 pts: existe ato normativo específico vigente que cria/institui a Ouvidoria de Serviços Penais ou núcleo especializado. 0 pt: não existe ato específico ou não há evidência suficiente. Sem o ato, a unidade é classificada como Não instituída. | D6: Resposta original consolidada do diagnóstico. | E6: Art. 6º, caput. | F6: 15 = instituída 0 = não instituída / sem evidência | G6: Pontuação automática. | H6: Sem ato, não há classificação ordinária de aderência. | I6: Doc. SEI 37070578
A7: AC | B7: Acre | C7: Sim | D7: Existe ato infralegal (portaria, resolução, ordem de serviço) que cria ouvidoria de serviços penais ou núcleo especializado | E7: Art. 6º, caput. | F7: =IF(C7="Sim",15,0) -> 15 | G7: =F7 -> 15 | H7: =IF(C7="Sim","Instituída",IF(C7="Não","Não instituída","Sem evidência")) -> Instituída | I7: Doc. SEI 37070578
A8: AL | B8: Alagoas | C8: Sim | D8: Existe lei ou decreto que cria ouvidoria de serviços penais ou núcleo especializado | E8: Art. 6º, caput. | F8: =IF(C8="Sim",15,0) -> 15 | G8: =F8 -> 15 | H8: =IF(C8="Sim","Instituída",IF(C8="Não","Não instituída","Sem evidência")) -> Instituída | I8: Doc. SEI 37070578
A9: AP | B9: Amapá | C9: Sim | D9: Existe lei ou decreto que cria ouvidoria de serviços penais ou núcleo especializado | E9: Art. 6º, caput. | F9: =IF(C9="Sim",15,0) -> 15 | G9: =F9 -> 15 | H9: =IF(C9="Sim","Instituída",IF(C9="Não","Não instituída","Sem evidência")) -> Instituída | I9: Doc. SEI 37070578
A10: AM | B10: Amazonas | C10: Sim | D10: Existe lei ou decreto que cria ouvidoria de serviços penais ou núcleo especializado | E10: Art. 6º, caput. | F10: =IF(C10="Sim",15,0) -> 15 | G10: =F10 -> 15 | H10: =IF(C10="Sim","Instituída",IF(C10="Não","Não instituída","Sem evidência")) -> Instituída | I10: Doc. SEI 37070578
A11: BA | B11: Bahia | C11: Sim | D11: Existe lei ou decreto que cria ouvidoria de serviços penais ou núcleo especializado | E11: Art. 6º, caput. | F11: =IF(C11="Sim",15,0) -> 15 | G11: =F11 -> 15 | H11: =IF(C11="Sim","Instituída",IF(C11="Não","Não instituída","Sem evidência")) -> Instituída | I11: Doc. SEI 37070578
A12: CE | B12: Ceará | C12: Sim | D12: Existe lei ou decreto que cria ouvidoria de serviços penais ou núcleo especializado | E12: Art. 6º, caput. | F12: =IF(C12="Sim",15,0) -> 15 | G12: =F12 -> 15 | H12: =IF(C12="Sim","Instituída",IF(C12="Não","Não instituída","Sem evidência")) -> Instituída | I12: Doc. SEI 37070578
A13: DF | B13: Distrito Federal | C13: Sim | D13: Existe lei ou decreto que cria ouvidoria de serviços penais ou núcleo especializado | E13: Art. 6º, caput. | F13: =IF(C13="Sim",15,0) -> 15 | G13: =F13 -> 15 | H13: =IF(C13="Sim","Instituída",IF(C13="Não","Não instituída","Sem evidência")) -> Instituída | I13: Doc. SEI 37070578
A14: ES | B14: Espírito Santo — Polícia Penal | C14: Sim | D14: Existe lei ou decreto que cria ouvidoria de serviços penais ou núcleo especializado | E14: Art. 6º, caput. | F14: =IF(C14="Sim",15,0) -> 15 | G14: =F14 -> 15 | H14: =IF(C14="Sim","Instituída",IF(C14="Não","Não instituída","Sem evidência")) -> Instituída | I14: Doc. SEI 37070578
A15: ES | B15: Espírito Santo — SEJUS/ES | C15: Sim | D15: Existe ato infralegal (portaria, resolução, ordem de serviço) que cria ouvidoria de serviços penais ou núcleo especializado | E15: Art. 6º, caput. | F15: =IF(C15="Sim",15,0) -> 15 | G15: =F15 -> 15 | H15: =IF(C15="Sim","Instituída",IF(C15="Não","Não instituída","Sem evidência")) -> Instituída | I15: Doc. SEI 37070578
A16: GO | B16: Goiás | C16: Sim | D16: Existe ato infralegal (portaria, resolução, ordem de serviço) que cria ouvidoria de serviços penais ou núcleo especializado | E16: Art. 6º, caput. | F16: =IF(C16="Sim",15,0) -> 15 | G16: =F16 -> 15 | H16: =IF(C16="Sim","Instituída",IF(C16="Não","Não instituída","Sem evidência")) -> Instituída | I16: Doc. SEI 37070578
A17: MA | B17: Maranhão | C17: Sim | D17: Existe lei ou decreto que cria ouvidoria de serviços penais ou núcleo especializado | E17: Art. 6º, caput. | F17: =IF(C17="Sim",15,0) -> 15 | G17: =F17 -> 15 | H17: =IF(C17="Sim","Instituída",IF(C17="Não","Não instituída","Sem evidência")) -> Instituída | I17: Doc. SEI 37070578
A18: MT | B18: Mato Grosso | C18: Sim | D18: Existe lei ou decreto que cria ouvidoria de serviços penais ou núcleo especializado | E18: Art. 6º, caput. | F18: =IF(C18="Sim",15,0) -> 15 | G18: =F18 -> 15 | H18: =IF(C18="Sim","Instituída",IF(C18="Não","Não instituída","Sem evidência")) -> Instituída | I18: Doc. SEI 37070578
... A32: SP | B32: São Paulo | C32: Sim | D32: Existe ato infralegal (portaria, resolução, ordem de serviço) que cria ouvidoria de serviços penais ou núcleo especializado | E32: Art. 6º, caput. | F32: =IF(C32="Sim",15,0) -> 15 | G32: =F32 -> 15 | H32: =IF(C32="Sim","Instituída",IF(C32="Não","Não instituída","Sem evidência")) -> Instituída | I32: Doc. SEI 37070578
A33: SE | B33: Sergipe | C33: Sim | D33: Sem resposta no diagnóstico | E33: Art. 6º, caput. | F33: =IF(C33="Sim",15,0) -> 15 | G33: =F33 -> 15 | H33: =IF(C33="Sim","Instituída",IF(C33="Não","Não instituída","Sem evidência")) -> Instituída
A34: TO | B34: Tocantins | C34: Não | D34: Não existe qualquer ato específico | E34: Art. 6º, caput. | F34: =IF(C34="Sim",15,0) -> 0 | G34: =F34 -> 0 | H34: =IF(C34="Sim","Instituída",IF(C34="Não","Não instituída","Sem evidência")) -> Não instituída | I34: Doc. SEI 37070578

Sheet 02_Autonomia
A1: 02 — Autonomia técnica e funcional
A2: Peso da dimensão: 15 pontos. Cada pergunta do diagnóstico pertence exclusivamente a uma única dimensão da matriz.
A4: Identificação | C4: Item 1 — Garantia normativa de autonomia técnica/funcional | K4: Item 2 — Condições institucionais de atuação sem interferência indevida | W4: Resultado da dimensão
A5: UF | B5: Unidade Federativa | C5: M3-56 — Vinculação institucional da Ouvidoria de Serviços Penais | D5: Resposta do diagnóstico | E5: Fundamentação na IN nº 75/2026 | F5: 3 pts | G5: M3-57 — Existência e designação do(a) Ouvidor(a) de Serviços Penais | H5: Resposta do diagnóstico | I5: Fundamentação na IN nº 75/2026 | J5: 3 pts | K5: M1-12 — Conteúdo do ato de criação da Ouvidoria de Serviços Penais | L5: Resposta do diagnóstico | M5: Fundamentação na IN nº 75/2026 | N5: 3 pts | O5: M4-67 — Fluxo de trabalho interno da Ouvidoria de Serviços Penais | P5: Resposta do diagnóstico | Q5: Fundamentação na IN nº 75/2026 | R5: 3 pts | S5: M4-68 — Prazos e qualidade da resposta às manifestações | T5: Resposta do diagnóstico | U5: Fundamentação na IN nº 75/2026 | V5: 3 pts | W5: Pontuação /15 | X5: Evidências / observações
A6: Como aplicar / resposta / fundamento → | C6: 3 pts: vinculada diretamente ao Gabinete/autoridade máxima, ou situação equivalente que assegure posição institucional autônoma. 1,5 pt: vinculada à estrutura central, sem subordinação a área operacional. 0 pt: vinculada a área operacional, não se aplica ou sem evidência. | D6: Resposta original consolidada do diagnóstico das Ouvidorias Estaduais de Serviços Penais. | E6: Art. 4º, I; art. 6º, §1º, I. | F6: 3 = atende 1.5 = parcial 0 = não atende / sem evidência | G6: 3 pts: há Ouvidor(a) formalmente designado(a) pela autoridade máxima ou autoridade superior equivalente. 1,5 pt: designação formal em condição intermediária. 0 pt: ponto focal informal, inexistência de Ouvidor específico ou sem evidência. | H6: Resposta original consolidada do diagnóstico das Ouvidorias Estaduais de Serviços Penais. | I6: Art. 4º, I; art. 8º, caput. | J6: 3 = atende 1.5 = parcial 0 = não atende / sem evidência | K6: 3 pts: o ato prevê simultaneamente dever de colaboração das áreas e prerrogativa de solicitar informações/documentos e requisitar apuração. 1,5 pt: apenas um desses elementos. 0 pt: nenhum ou sem evidência. | L6: Resposta original consolidada do diagnóstico das Ouvidorias Estaduais de Serviços Penais. | M6: Art. 6º, §1º, III; art. 10, II. | N6: 3 = atende 1.5 = parcial 0 = não atende / sem evidência | O6: 3 pts: fluxo formalizado e efetivamente utilizado, contemplando recebimento, registro, encaminhamento, acompanhamento e devolutiva. 1,5 pt: fluxo descrito, mas pouco aplicado. 0 pt: fluxo informal/inexistente ou sem evidência. | P6: Resposta original consolidada do diagnóstico das Ouvidorias Estaduais de Serviços Penais. | Q6: Art. 13, caput e incisos I a V. | R6: 3 = atende 1.5 = parcial 0 = não atende / sem evidência | S6: 3 pts: prazos claros e registrados, monitoramento e medidas diante de descumprimento. 1,5 pt: há prazos, mas sem controle sistemático. 0 pt: inexistência de prazos/monitoramento ou sem evidência. | T6: Resposta original consolidada do diagnóstico das Ouvidorias Estaduais de Serviços Penais. | U6: Art. 6º, §1º, IV; art. 10, II e IV; art. 13, IV e V. | V6: 3 = atende 1.5 = parcial 0 = não atende / sem evidência | W6: Soma automática das perguntas desta dimensão. | X6: Referência documental geral das respostas: Doc. SEI 37070578.
A7: AC | B7: Acre | C7: Atende | D7: Vinculada diretamente ao Gabinete ou à autoridade máxima do órgão gestor do sistema penal | E7: Art. 4º, I; art. 6º, §1º, I. | F7: =IF(C7="Atende",3,IF(C7="Parcial",1.5,0)) -> 3 | G7: Atende | H7: Há ouvidor(a) designado(a) formalmente pela autoridade máxima do órgão gestor do sistema penal | I7: Art. 4º, I; art. 8º, caput. | J7: =IF(G7="Atende",3,IF(G7="Parcial",1.5,0)) -> 3 | K7: Atende | L7: Indica a denominação da Ouvidoria de Serviços Penais e sua vinculação na estrutura organizacional do órgão;Define as competências básicas, compreendendo o recebimento, a análise, o encaminhamento e a resposta às manifestações;Especifica, entre o público atendido, cidadãos, servidores(as), pessoas privadas de liberdade e seus familiares;Garante a proteção da identidade do(a) manifestante e a confidencialidade das informações;Enuncia a finalidade da Ouvidoria de Serviços Penais como instância permanente de interlocução entre cidadãos, pessoas privadas de liberdade, familiares e servidores(as) penais e a administração penitenciária; | M7: Art. 6º, §1º, III; art. 10, II. | N7: =IF(K7="Atende",3,IF(K7="Parcial",1.5,0)) -> 3 | O7: Parcial | P7: Há fluxo descrito, mas pouco aplicado na prática | Q7: Art. 13, caput e incisos I a V. | R7: =IF(O7="Atende",3,IF(O7="Parcial",1.5,0)) -> 1.5 | S7: Atende | T7: Há prazos definidos (em norma ou ato interno), com tentativas de cumprimento, mas sem controle sistemático | U7: Art. 6º, §1º, IV; art. 10, II e IV; art. 13, IV e V. | V7: =IF(S7="Atende",3,IF(S7="Parcial",1.5,0)) -> 3 | W7: =SUM(F7,J7,N7,R7,V7) -> 13.5 | X7: Doc. SEI 37070578
A8: AL | B8: Alagoas | C8: Atende | D8: Vinculada diretamente ao Gabinete ou à autoridade máxima do órgão gestor do sistema penal | E8: Art. 4º, I; art. 6º, §1º, I. | F8: =IF(C8="Atende",3,IF(C8="Parcial",1.5,0)) -> 3 | G8: Atende | H8: Há ouvidor(a) designado(a) formalmente pela autoridade máxima do órgão gestor do sistema penal | I8: Art. 4º, I; art. 8º, caput. | J8: =IF(G8="Atende",3,IF(G8="Parcial",1.5,0)) -> 3 | K8: Não atende | L8: Não há normativa; | M8: Art. 6º, §1º, III; art. 10, II. | N8: =IF(K8="Atende",3,IF(K8="Parcial",1.5,0)) -> 0 | O8: Não atende | P8: Há fluxo informal (cada caso é tratado de forma diferente, sem padronização) | Q8: Art. 13, caput e incisos I a V. | R8: =IF(O8="Atende",3,IF(O8="Parcial",1.5,0)) -> 0 | S8: Atende | T8: Há prazos claros e registrados, com monitoramento das respostas das áreas e medidas adotadas em caso de descumprimento (cobrança, reencaminhamento, informação a instâncias superiores etc.) | U8: Art. 6º, §1º, IV; art. 10, II e IV; art. 13, IV e V. | V8: =IF(S8="Atende",3,IF(S8="Parcial",1.5,0)) -> 3 | W8: =SUM(F8,J8,N8,R8,V8) -> 9 | X8: Doc. SEI 37070578
A9: AP | B9: Amapá | C9: Atende | D9: Vinculada diretamente ao Gabinete ou à autoridade máxima do órgão gestor do sistema penal | E9: Art. 4º, I; art. 6º, §1º, I. | F9: =IF(C9="Atende",3,IF(C9="Parcial",1.5,0)) -> 3 | G9: Atende | H9: Há ouvidor(a) designado(a) formalmente pela autoridade máxima do órgão gestor do sistema penal | I9: Art. 4º, I; art. 8º, caput. | J9: =IF(G9="Atende",3,IF(G9="Parcial",1.5,0)) -> 3 | K9: Atende | L9: Indica a denominação da Ouvidoria de Serviços Penais e sua vinculação na estrutura organizacional do órgão;Estabelece prazos para resposta das áreas competentes e para devolutiva ao(à) manifestante;Define as competências básicas, compreendendo o recebimento, a análise, o encaminhamento e a resposta às manifestações;Garante a proteção da identidade do(a) manifestante e a confidencialidade das informações;Prevê que a resposta ao(à) manifestante deve ser prestada em linguagem clara, acessível e respeitosa;Determina que a Ouvidoria deve identificar padrões e tendências nas manifestações para elaborar diagnósticos e propor melhorias contínuas;Enuncia a finalidade da Ouvidoria de Serviços Penais como instância permanente de interlocução entre cidadãos, pessoas privadas de liberdade, familiares e servidores(as) penais e a administração penitenciária;Prevê que a Ouvidoria pode solicitar informações e documentos e requisitar apuração às áreas competentes, com prazos definidos; | M9: Art. 6º, §1º, III; art. 10, II. | N9: =IF(K9="Atende",3,IF(K9="Parcial",1.5,0)) -> 3 | O9: Atende | P9: Há fluxo formalizado e efetivamente utilizado, contemplando, no mínimo, recebimento, registro, encaminhamento à área competente, acompanhamento da resposta e devolutiva ao(à) manifestante, quando aplicável | Q9: Art. 13, caput e incisos I a V. | R9: =IF(O9="Atende",3,IF(O9="Parcial",1.5,0)) -> 3 | S9: Atende | T9: Há prazos claros e registrados, com monitoramento das respostas das áreas e medidas adotadas em caso de descumprimento (cobrança, reencaminhamento, informação a instâncias superiores etc.) | U9: Art. 6º, §1º, IV; art. 10, II e IV; art. 13, IV e V. | V9: =IF(S9="Atende",3,IF(S9="Parcial",1.5,0)) -> 3 | W9: =SUM(F9,J9,N9,R9,V9) -> 15 | X9: Doc. SEI 37070578
A10: AM | B10: Amazonas | C10: Atende | D10: Vinculada diretamente ao Gabinete ou à autoridade máxima do órgão gestor do sistema penal | E10: Art. 4º, I; art. 6º, §1º, I. | F10: =IF(C10="Atende",3,IF(C10="Parcial",1.5,0)) -> 3 | G10: Atende | H10: Há ouvidor(a) designado(a) formalmente pela autoridade máxima do órgão gestor do sistema penal | I10: Art. 4º, I; art. 8º, caput. | J10: =IF(G10="Atende",3,IF(G10="Parcial",1.5,0)) -> 3 | K10: Atende | L10: Indica a denominação da Ouvidoria de Serviços Penais e sua vinculação na estrutura organizacional do órgão;Define as competências básicas, compreendendo o recebimento, a análise, o encaminhamento e a resposta às manifestações;Especifica, entre o público atendido, cidadãos, servidores(as), pessoas privadas de liberdade e seus familiares;Estabelece o dever de colaboração das áreas técnicas e administrativas do órgão com as demandas encaminhadas pela Ouvidoria;Prevê que a Ouvidoria pode solicitar informações e documentos e requisitar apuração às áreas competentes, com prazos definidos;Estabelece prazos para resposta das áreas competentes e para devolutiva ao(à) manifestante;Garante a proteção da identidade do(a) manifestante e a confidencialidade das informações;Prevê que a resposta ao(à) manifestante deve ser prestada em linguagem clara, acessível e respeitosa;Determina que a Ouvidoria deve identificar padrões e tendências nas manifestações para elaborar diagnósticos e propor melhorias contínuas;Prevê a elaboração e publicação de relatórios periódicos de atividades, com dados estatísticos e indicadores de desempenho;Enuncia a finalidade da Ouvidoria de Serviços Penais como instância permanente de interlocução entre cidadãos, pessoas privadas de liberdade, familiares e servidores(as) penais e a administração penitenciária; | M10: Art. 6º, §1º, III; art. 10, II. | N10: =IF(K10="Atende",3,IF(K10="Parcial",1.5,0)) -> 3 | O10: Atende | P10: Há fluxo formalizado e efetivamente utilizado, contemplando, no mínimo, recebimento, registro, encaminhamento à área competente, acompanhamento da resposta e devolutiva ao(à) manifestante, quando aplicável | Q10: Art. 13, caput e incisos I a V. | R10: =IF(O10="Atende",3,IF(O10="Parcial",1.5,0)) -> 3 | S10: Atende | T10: Há prazos claros e registrados, com monitoramento das respostas das áreas e medidas adotadas em caso de descumprimento (cobrança, reencaminhamento, informação a instâncias superiores etc.) | U10: Art. 6º, §1º, IV; art. 10, II e IV; art. 13, IV e V. | V10: =IF(S10="Atende",3,IF(S10="Parcial",1.5,0)) -> 3 | W10: =SUM(F10,J10,N10,R10,V10) -> 15 | X10: Doc. SEI 37070578
A11: BA | B11: Bahia | C11: Atende | D11: Vinculada diretamente ao Gabinete ou à autoridade máxima do órgão gestor do sistema penal | E11: Art. 4º, I; art. 6º, §1º, I. | F11: =IF(C11="Atende",3,IF(C11="Parcial",1.5,0)) -> 3 | G11: Atende | H11: Há ouvidor(a) designado(a) formalmente pela autoridade máxima do órgão gestor do sistema penal | I11: Art. 4º, I; art. 8º, caput. | J11: =IF(G11="Atende",3,IF(G11="Parcial",1.5,0)) -> 3 | K11: Atende | L11: Indica a denominação da Ouvidoria de Serviços Penais e sua vinculação na estrutura organizacional do órgão;Define as competências básicas, compreendendo o recebimento, a análise, o encaminhamento e a resposta às manifestações; | M11: Art. 6º, §1º, III; art. 10, II. | N11: =IF(K11="Atende",3,IF(K11="Parcial",1.5,0)) -> 3 | O11: Atende | P11: Há fluxo formalizado e efetivamente utilizado, contemplando, no mínimo, recebimento, registro, encaminhamento à área competente, acompanhamento da resposta e devolutiva ao(à) manifestante, quando aplicável | Q11: Art. 13, caput e incisos I a V. | R11: =IF(O11="Atende",3,IF(O11="Parcial",1.5,0)) -> 3 | S11: Atende | T11: Há prazos claros e registrados, com monitoramento das respostas das áreas e medidas adotadas em caso de descumprimento (cobrança, reencaminhamento, informação a instâncias superiores etc.) | U11: Art. 6º, §1º, IV; art. 10, II e IV; art. 13, IV e V. | V11: =IF(S11="Atende",3,IF(S11="Parcial",1.5,0)) -> 3 | W11: =SUM(F11,J11,N11,R11,V11) -> 15 | X11: Doc. SEI 37070578
A12: CE | B12: Ceará | C12: Atende | D12: Vinculada diretamente ao Gabinete ou à autoridade máxima do órgão gestor do sistema penal | E12: Art. 4º, I; art. 6º, §1º, I. | F12: =IF(C12="Atende",3,IF(C12="Parcial",1.5,0)) -> 3 | G12: Atende | H12: Há ouvidor(a) designado(a) formalmente pela autoridade máxima do órgão gestor do sistema penal | I12: Art. 4º, I; art. 8º, caput. | J12: =IF(G12="Atende",3,IF(G12="Parcial",1.5,0)) -> 3 | K12: Atende | L12: Indica a denominação da Ouvidoria de Serviços Penais e sua vinculação na estrutura organizacional do órgão;Define as competências básicas, compreendendo o recebimento, a análise, o encaminhamento e a resposta às manifestações;Especifica, entre o público atendido, cidadãos, servidores(as), pessoas privadas de liberdade e seus familiares;Estabelece o dever de colaboração das áreas técnicas e administrativas do órgão com as demandas encaminhadas pela Ouvidoria;Prevê que a Ouvidoria pode solicitar informações e documentos e requisitar apuração às áreas competentes, com prazos definidos;Estabelece prazos para resposta das áreas competentes e para devolutiva ao(à) manifestante;Garante a proteção da identidade do(a) manifestante e a confidencialidade das informações;Prevê que a resposta ao(à) manifestante deve ser prestada em linguagem clara, acessível e respeitosa;Determina que a Ouvidoria deve identificar padrões e tendências nas manifestações para elaborar diagnósticos e propor melhorias contínuas;Prevê a elaboração e publicação de relatórios periódicos de atividades, com dados estatísticos e indicadores de desempenho;Enuncia a finalidade da Ouvidoria de Serviços Penais como instância permanente de interlocução entre cidadãos, pessoas privadas de liberdade, familiares e servidores(as) penais e a administração penitenciária; | M12: Art. 6º, §1º, III; art. 10, II. | N12: =IF(K12="Atende",3,IF(K12="Parcial",1.5,0)) -> 3 | O12: Atende | P12: Há fluxo formalizado e efetivamente utilizado, contemplando, no mínimo, recebimento, registro, encaminhamento à área competente, acompanhamento da resposta e devolutiva ao(à) manifestante, quando aplicável | Q12: Art. 13, caput e incisos I a V. | R12: =IF(O12="Atende",3,IF(O12="Parcial",1.5,0)) -> 3 | S12: Atende | T12: Há prazos claros e registrados, com monitoramento das respostas das áreas e medidas adotadas em caso de descumprimento (cobrança, reencaminhamento, informação a instâncias superiores etc.) | U12: Art. 6º, §1º, IV; art. 10, II e IV; art. 13, IV e V. | V12: =IF(S12="Atende",3,IF(S12="Parcial",1.5,0)) -> 3 | W12: =SUM(F12,J12,N12,R12,V12) -> 15 | X12: Doc. SEI 37070578
A13: DF | B13: Distrito Federal | C13: Atende | D13: Vinculada diretamente ao Gabinete ou à autoridade máxima do órgão gestor do sistema penal | E13: Art. 4º, I; art. 6º, §1º, I. | F13: =IF(C13="Atende",3,IF(C13="Parcial",1.5,0)) -> 3 | G13: Atende | H13: Há ouvidor(a) designado(a) formalmente pela autoridade máxima do órgão gestor do sistema penal | I13: Art. 4º, I; art. 8º, caput. | J13: =IF(G13="Atende",3,IF(G13="Parcial",1.5,0)) -> 3 | K13: Não atende | L13: Indica a denominação da Ouvidoria de Serviços Penais e sua vinculação na estrutura organizacional do órgão; | M13: Art. 6º, §1º, III; art. 10, II. | N13: =IF(K13="Atende",3,IF(K13="Parcial",1.5,0)) -> 0 | O13: Atende | P13: Há fluxo formalizado e efetivamente utilizado, contemplando, no mínimo, recebimento, registro, encaminhamento à área competente, acompanhamento da resposta e devolutiva ao(à) manifestante, quando aplicável | Q13: Art. 13, caput e incisos I a V. | R13: =IF(O13="Atende",3,IF(O13="Parcial",1.5,0)) -> 3 | S13: Atende | T13: Há prazos claros e registrados, com monitoramento das respostas das áreas e medidas adotadas em caso de descumprimento (cobrança, reencaminhamento, informação a instâncias superiores etc.) | U13: Art. 6º, §1º, IV; art. 10, II e IV; art. 13, IV e V. | V13: =IF(S13="Atende",3,IF(S13="Parcial",1.5,0)) -> 3 | W13: =SUM(F13,J13,N13,R13,V13) -> 12 | X13: Doc. SEI 37070578
A14: ES | B14: Espírito Santo — Polícia Penal | C14: Atende | D14: Vinculada diretamente ao Gabinete ou à autoridade máxima do órgão gestor do sistema penal | E14: Art. 4º, I; art. 6º, §1º, I. | F14: =IF(C14="Atende",3,IF(C14="Parcial",1.5,0)) -> 3 | G14: Atende | H14: Há ouvidor(a) designado(a) formalmente pela autoridade máxima do órgão gestor do sistema penal | I14: Art. 4º, I; art. 8º, caput. | J14: =IF(G14="Atende",3,IF(G14="Parcial",1.5,0)) -> 3 | K14: Atende | L14: Estabelece prazos para resposta das áreas competentes e para devolutiva ao(à) manifestante;Prevê que a Ouvidoria pode solicitar informações e documentos e requisitar apuração às áreas competentes, com prazos definidos;Estabelece o dever de colaboração das áreas técnicas e administrativas do órgão com as demandas encaminhadas pela Ouvidoria;Define as competências básicas, compreendendo o recebimento, a análise, o encaminhamento e a resposta às manifestações;Garante a proteção da identidade do(a) manifestante e a confidencialidade das informações;Define mandato, regras de substituição e regras de confidencialidade aplicáveis ao(à) Ouvidor(a) e à equipe;Prevê que a resposta ao(à) manifestante deve ser prestada em linguagem clara, acessível e respeitosa;Indica a denominação da Ouvidoria de Serviços Penais e sua vinculação na estrutura organizacional do órgão; | M14: Art. 6º, §1º, III; art. 10, II. | N14: =IF(K14="Atende",3,IF(K14="Parcial",1.5,0)) -> 3 | O14: Atende | P14: Há fluxo formalizado e efetivamente utilizado, contemplando, no mínimo, recebimento, registro, encaminhamento à área competente, acompanhamento da resposta e devolutiva ao(à) manifestante, quando aplicável | Q14: Art. 13, caput e incisos I a V. | R14: =IF(O14="Atende",3,IF(O14="Parcial",1.5,0)) -> 3 | S14: Atende | T14: Há prazos claros e registrados, com monitoramento das respostas das áreas e medidas adotadas em caso de descumprimento (cobrança, reencaminhamento, informação a instâncias superiores etc.) | U14: Art. 6º, §1º, IV; art. 10, II e IV; art. 13, IV e V. | V14: =IF(S14="Atende",3,IF(S14="Parcial",1.5,0)) -> 3 | W14: =SUM(F14,J14,N14,R14,V14) -> 15 | X14: Doc. SEI 37070578
A15: ES | B15: Espírito Santo — SEJUS/ES | C15: Atende | D15: Vinculada diretamente ao Gabinete ou à autoridade máxima do órgão gestor do sistema penal | E15: Art. 4º, I; art. 6º, §1º, I. | F15: =IF(C15="Atende",3,IF(C15="Parcial",1.5,0)) -> 3 | G15: Atende | H15: Há ouvidor(a) designado(a) formalmente pela autoridade máxima do órgão gestor do sistema penal | I15: Art. 4º, I; art. 8º, caput. | J15: =IF(G15="Atende",3,IF(G15="Parcial",1.5,0)) -> 3 | K15: Atende | L15: Prevê que a Ouvidoria pode solicitar informações e documentos e requisitar apuração às áreas competentes, com prazos definidos;Estabelece prazos para resposta das áreas competentes e para devolutiva ao(à) manifestante;Garante a proteção da identidade do(a) manifestante e a confidencialidade das informações;Prevê que a resposta ao(à) manifestante deve ser prestada em linguagem clara, acessível e respeitosa;Define as competências básicas, compreendendo o recebimento, a análise, o encaminhamento e a resposta às manifestações;Estabelece o dever de colaboração das áreas técnicas e administrativas do órgão com as demandas encaminhadas pela Ouvidoria; | M15: Art. 6º, §1º, III; art. 10, II. | N15: =IF(K15="Atende",3,IF(K15="Parcial",1.5,0)) -> 3 | O15: Atende | P15: Há fluxo formalizado e efetivamente utilizado, contemplando, no mínimo, recebimento, registro, encaminhamento à área competente, acompanhamento da resposta e devolutiva ao(à) manifestante, quando aplicável | Q15: Art. 13, caput e incisos I a V. | R15: =IF(O15="Atende",3,IF(O15="Parcial",1.5,0)) -> 3 | S15: Atende | T15: Há prazos claros e registrados, com monitoramento das respostas das áreas e medidas adotadas em caso de descumprimento (cobrança, reencaminhamento, informação a instâncias superiores etc.) | U15: Art. 6º, §1º, IV; art. 10, II e IV; art. 13, IV e V. | V15: =IF(S15="Atende",3,IF(S15="Parcial",1.5,0)) -> 3 | W15: =SUM(F15,J15,N15,R15,V15) -> 15 | X15: Doc. SEI 37070578
A16: GO | B16: Goiás | C16: Atende | D16: Vinculada diretamente ao Gabinete ou à autoridade máxima do órgão gestor do sistema penal | E16: Art. 4º, I; art. 6º, §1º, I. | F16: =IF(C16="Atende",3,IF(C16="Parcial",1.5,0)) -> 3 | G16: Atende | H16: Há ouvidor(a) designado(a) formalmente pela autoridade máxima do órgão gestor do sistema penal | I16: Art. 4º, I; art. 8º, caput. | J16: =IF(G16="Atende",3,IF(G16="Parcial",1.5,0)) -> 3 | K16: Atende | L16: Define mandato, regras de substituição e regras de confidencialidade aplicáveis ao(à) Ouvidor(a) e à equipe;Enuncia a finalidade da Ouvidoria de Serviços Penais como instância permanente de interlocução entre cidadãos, pessoas privadas de liberdade, familiares e servidores(as) penais e a administração penitenciária;Prevê a elaboração e publicação de relatórios periódicos de atividades, com dados estatísticos e indicadores de desempenho;Determina que a Ouvidoria deve identificar padrões e tendências nas manifestações para elaborar diagnósticos e propor melhorias contínuas;Prevê que a resposta ao(à) manifestante deve ser prestada em linguagem clara, acessível e respeitosa;Garante a proteção da identidade do(a) manifestante e a confidencialidade das informações;Estabelece prazos para resposta das áreas competentes e para devolutiva ao(à) manifestante;Prevê que a Ouvidoria pode solicitar informações e documentos e requisitar apuração às áreas competentes, com prazos definidos;Estabelece o dever de colaboração das áreas técnicas e administrativas do órgão com as demandas encaminhadas pela Ouvidoria;Especifica, entre o público atendido, cidadãos, servidores(as), pessoas privadas de liberdade e seus familiares;Define as competências básicas, compreendendo o recebimento, a análise, o encaminhamento e a resposta às manifestações;Indica a denominação da Ouvidoria de Serviços Penais e sua vinculação na estrutura organizacional do órgão; | M16: Art. 6º, §1º, III; art. 10, II. | N16: =IF(K16="Atende",3,IF(K16="Parcial",1.5,0)) -> 3 | O16: Atende | P16: Há fluxo formalizado e efetivamente utilizado, contemplando, no mínimo, recebimento, registro, encaminhamento à área competente, acompanhamento da resposta e devolutiva ao(à) manifestante, quando aplicável | Q16: Art. 13, caput e incisos I a V. | R16: =IF(O16="Atende",3,IF(O16="Parcial",1.5,0)) -> 3 | S16: Atende | T16: Há prazos claros e registrados, com monitoramento das respostas das áreas e medidas adotadas em caso de descumprimento (cobrança, reencaminhamento, informação a instâncias superiores etc.) | U16: Art. 6º, §1º, IV; art. 10, II e IV; art. 13, IV e V. | V16: =IF(S16="Atende",3,IF(S16="Parcial",1.5,0)) -> 3 | W16: =SUM(F16,J16,N16,R16,V16) -> 15 | X16: Doc. SEI 37070578
A17: MA | B17: Maranhão | C17: Atende | D17: Vinculada diretamente ao Gabinete ou à autoridade máxima do órgão gestor do sistema penal | E17: Art. 4º, I; art. 6º, §1º, I. | F17: =IF(C17="Atende",3,IF(C17="Parcial",1.5,0)) -> 3 | G17: Atende | H17: Há ouvidor(a) designado(a) formalmente pela autoridade máxima do órgão gestor do sistema penal | I17: Art. 4º, I; art. 8º, caput. | J17: =IF(G17="Atende",3,IF(G17="Parcial",1.5,0)) -> 3 | K17: Atende | L17: Indica a denominação da Ouvidoria de Serviços Penais e sua vinculação na estrutura organizacional do órgão;Define as competências básicas, compreendendo o recebimento, a análise, o encaminhamento e a resposta às manifestações;Estabelece o dever de colaboração das áreas técnicas e administrativas do órgão com as demandas encaminhadas pela Ouvidoria;Enuncia a finalidade da Ouvidoria de Serviços Penais como instância permanente de interlocução entre cidadãos, pessoas privadas de liberdade, familiares e servidores(as) penais e a administração penitenciária;Determina que a Ouvidoria deve identificar padrões e tendências nas manifestações para elaborar diagnósticos e propor melhorias contínuas;Prevê que a Ouvidoria pode solicitar informações e documentos e requisitar apuração às áreas competentes, com prazos definidos;Especifica, entre o público atendido, cidadãos, servidores(as), pessoas privadas de liberdade e seus familiares; | M17: Art. 6º, §1º, III; art. 10, II. | N17: =IF(K17="Atende",3,IF(K17="Parcial",1.5,0)) -> 3 | O17: Atende | P17: Há fluxo formalizado e efetivamente utilizado, contemplando, no mínimo, recebimento, registro, encaminhamento à área competente, acompanhamento da resposta e devolutiva ao(à) manifestante, quando aplicável | Q17: Art. 13, caput e incisos I a V. | R17: =IF(O17="Atende",3,IF(O17="Parcial",1.5,0)) -> 3 | S17: Atende | T17: Há prazos claros e registrados, com monitoramento das respostas das áreas e medidas adotadas em caso de descumprimento (cobrança, reencaminhamento, informação a instâncias superiores etc.) | U17: Art. 6º, §1º, IV; art. 10, II e IV; art. 13, IV e V. | V17: =IF(S17="Atende",3,IF(S17="Parcial",1.5,0)) -> 3 | W17: =SUM(F17,J17,N17,R17,V17) -> 15 | X17: Doc. SEI 37070578
A18: MT | B18: Mato Grosso | C18: Atende | D18: Vinculada diretamente ao Gabinete ou à autoridade máxima do órgão gestor do sistema penal | E18: Art. 4º, I; art. 6º, §1º, I. | F18: =IF(C18="Atende",3,IF(C18="Parcial",1.5,0)) -> 3 | G18: Atende | H18: Há ouvidor(a) designado(a) formalmente pela autoridade máxima do órgão gestor do sistema penal | I18: Art. 4º, I; art. 8º, caput. | J18: =IF(G18="Atende",3,IF(G18="Parcial",1.5,0)) -> 3 | K18: Atende | L18: Indica a denominação da Ouvidoria de Serviços Penais e sua vinculação na estrutura organizacional do órgão;Define as competências básicas, compreendendo o recebimento, a análise, o encaminhamento e a resposta às manifestações;Especifica, entre o público atendido, cidadãos, servidores(as), pessoas privadas de liberdade e seus familiares;Estabelece o dever de colaboração das áreas técnicas e administrativas do órgão com as demandas encaminhadas pela Ouvidoria;Estabelece prazos para resposta das áreas competentes e para devolutiva ao(à) manifestante;Garante a proteção da identidade do(a) manifestante e a confidencialidade das informações;Prevê que a resposta ao(à) manifestante deve ser prestada em linguagem clara, acessível e respeitosa;Determina que a Ouvidoria deve identificar padrões e tendências nas manifestações para elaborar diagnósticos e propor melhorias contínuas;Prevê a elaboração e publicação de relatórios periódicos de atividades, com dados estatísticos e indicadores de desempenho;Enuncia a finalidade da Ouvidoria de Serviços Penais como instância permanente de interlocução entre cidadãos, pessoas privadas de liberdade, familiares e servidores(as) penais e a administração penitenciária;Define mandato, regras de substituição e regras de confidencialidade aplicáveis ao(à) Ouvidor(a) e à equipe;Prevê que a Ouvidoria pode solicitar informações e documentos e requisitar apuração às áreas competentes, com prazos definidos; | M18: Art. 6º, §1º, III; art. 10, II. | N18: =IF(K18="Atende",3,IF(K18="Parcial",1.5,0)) -> 3 | O18: Atende | P18: Há fluxo formalizado e efetivamente utilizado, contemplando, no mínimo, recebimento, registro, encaminhamento à área competente, acompanhamento da resposta e devolutiva ao(à) manifestante, quando aplicável | Q18: Art. 13, caput e incisos I a V. | R18: =IF(O18="Atende",3,IF(O18="Parcial",1.5,0)) -> 3 | S18: Atende | T18: Há prazos claros e registrados, com monitoramento das respostas das áreas e medidas adotadas em caso de descumprimento (cobrança, reencaminhamento, informação a instâncias superiores etc.) | U18: Art. 6º, §1º, IV; art. 10, II e IV; art. 13, IV e V. | V18: =IF(S18="Atende",3,IF(S18="Parcial",1.5,0)) -> 3 | W18: =SUM(F18,J18,N18,R18,V18) -> 15 | X18: Doc. SEI 37070578
... A32: SP | B32: São Paulo | C32: Atende | D32: Vinculada diretamente ao Gabinete ou à autoridade máxima do órgão gestor do sistema penal | E32: Art. 4º, I; art. 6º, §1º, I. | F32: =IF(C32="Atende",3,IF(C32="Parcial",1.5,0)) -> 3 | G32: Atende | H32: Há ouvidor(a) designado(a) formalmente pela autoridade máxima do órgão gestor do sistema penal | I32: Art. 4º, I; art. 8º, caput. | J32: =IF(G32="Atende",3,IF(G32="Parcial",1.5,0)) -> 3 | K32: Atende | L32: Especifica, entre o público atendido, cidadãos, servidores(as), pessoas privadas de liberdade e seus familiares;Define as competências básicas, compreendendo o recebimento, a análise, o encaminhamento e a resposta às manifestações;Indica a denominação da Ouvidoria de Serviços Penais e sua vinculação na estrutura organizacional do órgão;Estabelece o dever de colaboração das áreas técnicas e administrativas do órgão com as demandas encaminhadas pela Ouvidoria;Prevê que a Ouvidoria pode solicitar informações e documentos e requisitar apuração às áreas competentes, com prazos definidos;Estabelece prazos para resposta das áreas competentes e para devolutiva ao(à) manifestante;Prevê que a resposta ao(à) manifestante deve ser prestada em linguagem clara, acessível e respeitosa;Garante a proteção da identidade do(a) manifestante e a confidencialidade das informações;Determina que a Ouvidoria deve identificar padrões e tendências nas manifestações para elaborar diagnósticos e propor melhorias contínuas;Prevê a elaboração e publicação de relatórios periódicos de atividades, com dados estatísticos e indicadores de desempenho;Enuncia a finalidade da Ouvidoria de Serviços Penais como instância permanente de interlocução entre cidadãos, pessoas privadas de liberdade, familiares e servidores(as) penais e a administração penitenciária;Define mandato, regras de substituição e regras de confidencialidade aplicáveis ao(à) Ouvidor(a) e à equipe; | M32: Art. 6º, §1º, III; art. 10, II. | N32: =IF(K32="Atende",3,IF(K32="Parcial",1.5,0)) -> 3 | O32: Atende | P32: Há fluxo formalizado e efetivamente utilizado, contemplando, no mínimo, recebimento, registro, encaminhamento à área competente, acompanhamento da resposta e devolutiva ao(à) manifestante, quando aplicável | Q32: Art. 13, caput e incisos I a V. | R32: =IF(O32="Atende",3,IF(O32="Parcial",1.5,0)) -> 3 | S32: Atende | T32: Há prazos claros e registrados, com monitoramento das respostas das áreas e medidas adotadas em caso de descumprimento (cobrança, reencaminhamento, informação a instâncias superiores etc.) | U32: Art. 6º, §1º, IV; art. 10, II e IV; art. 13, IV e V. | V32: =IF(S32="Atende",3,IF(S32="Parcial",1.5,0)) -> 3 | W32: =SUM(F32,J32,N32,R32,V32) -> 15 | X32: Doc. SEI 37070578
A33: SE | B33: Sergipe | C33: Sem evidência | D33: Sem resposta no diagnóstico | E33: Art. 4º, I; art. 6º, §1º, I. | F33: =IF(C33="Atende",3,IF(C33="Parcial",1.5,0)) -> 0 | G33: Sem evidência | H33: Sem resposta no diagnóstico | I33: Art. 4º, I; art. 8º, caput. | J33: =IF(G33="Atende",3,IF(G33="Parcial",1.5,0)) -> 0 | K33: Não atende | L33: Sem resposta no diagnóstico | M33: Art. 6º, §1º, III; art. 10, II. | N33: =IF(K33="Atende",3,IF(K33="Parcial",1.5,0)) -> 0 | P33: Sem resposta no diagnóstico | Q33: Art. 13, caput e incisos I a V. | R33: =IF(O33="Atende",3,IF(O33="Parcial",1.5,0)) -> 0 | S33: Não atende | T33: Sem resposta no diagnóstico | U33: Art. 6º, §1º, IV; art. 10, II e IV; art. 13, IV e V. | V33: =IF(S33="Atende",3,IF(S33="Parcial",1.5,0)) -> 0 | W33: =SUM(F33,J33,N33,R33,V33) -> 0 | X33: Doc. SEI 37070578
A34: TO | B34: Tocantins | C34: Não atende | D34: Não se aplica (não há ouvidoria própria prevista) | E34: Art. 4º, I; art. 6º, §1º, I. | F34: =IF(C34="Atende",3,IF(C34="Parcial",1.5,0)) -> 0 | G34: Não atende | H34: Há ouvidor(a) designado(a) formalmente pela autoridade máxima do órgão gestor do sistema penal | I34: Art. 4º, I; art. 8º, caput. | J34: =IF(G34="Atende",3,IF(G34="Parcial",1.5,0)) -> 0 | K34: Não atende | L34: Não há normativa; | M34: Art. 6º, §1º, III; art. 10, II. | N34: =IF(K34="Atende",3,IF(K34="Parcial",1.5,0)) -> 0 | P34: Há fluxo formalizado e efetivamente utilizado, contemplando, no mínimo, recebimento, registro, encaminhamento à área competente, acompanhamento da resposta e devolutiva ao(à) manifestante, quando aplicável | Q34: Art. 13, caput e incisos I a V. | R34: =IF(O34="Atende",3,IF(O34="Parcial",1.5,0)) -> 0 | T34: Há prazos claros e registrados, com monitoramento das respostas das áreas e medidas adotadas em caso de descumprimento (cobrança, reencaminhamento, informação a instâncias superiores etc.) | U34: Art. 6º, §1º, IV; art. 10, II e IV; art. 13, IV e V. | V34: =IF(S34="Atende",3,IF(S34="Parcial",1.5,0)) -> 0 | W34: =SUM(F34,J34,N34,R34,V34) -> 0 | X34: Doc. SEI 37070578

Sheet 03_Imparcialidade
A1: 03 — Imparcialidade, sigilo e proteção
A2: Peso da dimensão: 15 pontos. Cada pergunta do diagnóstico pertence exclusivamente a uma única dimensão da matriz.
A4: Identificação | C4: Item 1 — Proteção e tratamento de denúncias graves e sensíveis | G4: Item 2 — Confidencialidade e sigilo da equipe | K4: Resultado da dimensão
A5: UF | B5: Unidade Federativa | C5: M4-69 — Tratamento de denúncias graves e sensíveis | D5: Resposta do diagnóstico | E5: Fundamentação na IN nº 75/2026 | F5: 8 pts | G5: M3-63 — Compromisso de sigilo da equipe | H5: Resposta do diagnóstico | I5: Fundamentação na IN nº 75/2026 | J5: 7 pts | K5: Pontuação /15 | L5: Evidências / observações
A6: Como aplicar / resposta / fundamento → | C6: 8 pts: há tratamento específico para denúncias graves/sensíveis, com proteção da identidade, sigilo reforçado ou restrição de acesso e encaminhamento adequado. 4 pts: tratamento diferenciado, mas incompleto. 0 pt: inexistência de proteção específica ou sem evidência. | D6: Resposta original consolidada do diagnóstico das Ouvidorias Estaduais de Serviços Penais. | E6: Art. 4º, II e §2º; art. 10, III. | F6: 8 = atende 4 = parcial 0 = não atende / sem evidência | G6: 7 pts: equipe e colaboradores possuem compromisso formal de sigilo. 3,5 pts: compromisso parcial, informal ou não abrangente. 0 pt: inexistente ou sem evidência. | H6: Resposta original consolidada do diagnóstico das Ouvidorias Estaduais de Serviços Penais. | I6: Art. 9º, §4º. | J6: 7 = atende 3.5 = parcial 0 = não atende / sem evidência | K6: Soma automática das perguntas desta dimensão. | L6: Referência documental geral das respostas: Doc. SEI 37070578.
A7: AC | B7: Acre | C7: Atende | D7: Protocolo para situações de risco à vida ou à integridade de pessoas privadas de liberdade; | E7: Art. 4º, II e §2º; art. 10, III. | F7: =IF(C7="Atende",8,IF(C7="Parcial",4,0)) -> 8 | G7: Parcial | H7: Há cláusulas genéricas de sigilo em códigos de ética ou normativos equivalentes | I7: Art. 9º, §4º. | J7: =IF(G7="Atende",7,IF(G7="Parcial",3.5,0)) -> 3.5 | K7: =SUM(F7,J7) -> 11.5 | L7: Doc. SEI 37070578
A8: AL | B8: Alagoas | C8: Atende | D8: Protocolo para situações de risco à vida ou à integridade de pessoas privadas de liberdade;Protocolo para casos de tortura ou tratamento cruel, desumano ou degradante em unidades penais;Protocolo para outras formas de violência institucional em unidades penais;Protocolo para assédio moral ou sexual envolvendo servidores(as) penais;Protocolo para ameaças, retaliações ou perseguições contra servidores(as) penais em razão de manifestações ou denúncias;Protocolo para corrupção e irregularidades graves na gestão dos serviços penais;Procedimentos de sigilo reforçado, restrição de acesso e fluxos de emergência para esses casos; | E8: Art. 4º, II e §2º; art. 10, III. | F8: =IF(C8="Atende",8,IF(C8="Parcial",4,0)) -> 8 | G8: Não atende | H8: Não há qualquer instrumento formal de sigilo para a equipe da Ouvidoria | I8: Art. 9º, §4º. | J8: =IF(G8="Atende",7,IF(G8="Parcial",3.5,0)) -> 0 | K8: =SUM(F8,J8) -> 8 | L8: Doc. SEI 37070578
A9: AP | B9: Amapá | C9: Atende | D9: Protocolo para casos de tortura ou tratamento cruel, desumano ou degradante em unidades penais;Protocolo para ameaças, retaliações ou perseguições contra servidores(as) penais em razão de manifestações ou denúncias; | E9: Art. 4º, II e §2º; art. 10, III. | F9: =IF(C9="Atende",8,IF(C9="Parcial",4,0)) -> 8 | G9: Atende | H9: A equipe assina Termo de Compromisso de Manutenção de Sigilo Funcional específico para atuação na Ouvidoria de Serviços Penais | I9: Art. 9º, §4º. | J9: =IF(G9="Atende",7,IF(G9="Parcial",3.5,0)) -> 7 | K9: =SUM(F9,J9) -> 15 | L9: Doc. SEI 37070578
A10: AM | B10: Amazonas | C10: Atende | D10: Protocolo para situações de risco à vida ou à integridade de pessoas privadas de liberdade;Protocolo para casos de tortura ou tratamento cruel, desumano ou degradante em unidades penais;Protocolo para outras formas de violência institucional em unidades penais;Protocolo para assédio moral ou sexual envolvendo servidores(as) penais;Protocolo para ameaças, retaliações ou perseguições contra servidores(as) penais em razão de manifestações ou denúncias;Protocolo para corrupção e irregularidades graves na gestão dos serviços penais;Procedimentos de sigilo reforçado, restrição de acesso e fluxos de emergência para esses casos; | E10: Art. 4º, II e §2º; art. 10, III. | F10: =IF(C10="Atende",8,IF(C10="Parcial",4,0)) -> 8 | G10: Atende | H10: Além do termo, há rotinas de reforço e capacitação periódica sobre sigilo e proteção de dados pessoais | I10: Art. 9º, §4º. | J10: =IF(G10="Atende",7,IF(G10="Parcial",3.5,0)) -> 7 | K10: =SUM(F10,J10) -> 15 | L10: Doc. SEI 37070578
A11: BA | B11: Bahia | C11: Atende | D11: Protocolo para ameaças, retaliações ou perseguições contra servidores(as) penais em razão de manifestações ou denúncias;Protocolo para assédio moral ou sexual envolvendo servidores(as) penais;Protocolo para outras formas de violência institucional em unidades penais;Protocolo para situações de risco à vida ou à integridade de pessoas privadas de liberdade;Protocolo para casos de tortura ou tratamento cruel, desumano ou degradante em unidades penais; | E11: Art. 4º, II e §2º; art. 10, III. | F11: =IF(C11="Atende",8,IF(C11="Parcial",4,0)) -> 8 | G11: Atende | H11: A equipe assina Termo de Compromisso de Manutenção de Sigilo Funcional específico para atuação na Ouvidoria de Serviços Penais | I11: Art. 9º, §4º. | J11: =IF(G11="Atende",7,IF(G11="Parcial",3.5,0)) -> 7 | K11: =SUM(F11,J11) -> 15 | L11: Doc. SEI 37070578
A12: CE | B12: Ceará | C12: Atende | D12: Protocolo para casos de tortura ou tratamento cruel, desumano ou degradante em unidades penais; | E12: Art. 4º, II e §2º; art. 10, III. | F12: =IF(C12="Atende",8,IF(C12="Parcial",4,0)) -> 8 | G12: Atende | H12: Além do termo, há rotinas de reforço e capacitação periódica sobre sigilo e proteção de dados pessoais | I12: Art. 9º, §4º. | J12: =IF(G12="Atende",7,IF(G12="Parcial",3.5,0)) -> 7 | K12: =SUM(F12,J12) -> 15 | L12: Doc. SEI 37070578
A13: DF | B13: Distrito Federal | C13: Atende | D13: Procedimentos de sigilo reforçado, restrição de acesso e fluxos de emergência para esses casos;Protocolo para assédio moral ou sexual envolvendo servidores(as) penais; | E13: Art. 4º, II e §2º; art. 10, III. | F13: =IF(C13="Atende",8,IF(C13="Parcial",4,0)) -> 8 | G13: Atende | H13: Além do termo, há rotinas de reforço e capacitação periódica sobre sigilo e proteção de dados pessoais | I13: Art. 9º, §4º. | J13: =IF(G13="Atende",7,IF(G13="Parcial",3.5,0)) -> 7 | K13: =SUM(F13,J13) -> 15 | L13: Doc. SEI 37070578
A14: ES | B14: Espírito Santo — Polícia Penal | C14: Atende | D14: Protocolo para situações de risco à vida ou à integridade de pessoas privadas de liberdade;Protocolo para casos de tortura ou tratamento cruel, desumano ou degradante em unidades penais;Protocolo para outras formas de violência institucional em unidades penais;Protocolo para assédio moral ou sexual envolvendo servidores(as) penais;Protocolo para ameaças, retaliações ou perseguições contra servidores(as) penais em razão de manifestações ou denúncias;Procedimentos de sigilo reforçado, restrição de acesso e fluxos de emergência para esses casos;Protocolo para corrupção e irregularidades graves na gestão dos serviços penais; | E14: Art. 4º, II e §2º; art. 10, III. | F14: =IF(C14="Atende",8,IF(C14="Parcial",4,0)) -> 8 | G14: Atende | H14: Além do termo, há rotinas de reforço e capacitação periódica sobre sigilo e proteção de dados pessoais | I14: Art. 9º, §4º. | J14: =IF(G14="Atende",7,IF(G14="Parcial",3.5,0)) -> 7 | K14: =SUM(F14,J14) -> 15 | L14: Doc. SEI 37070578
A15: ES | B15: Espírito Santo — SEJUS/ES | C15: Parcial | D15: Protocolo para assédio moral ou sexual envolvendo servidores(as) penais; | E15: Art. 4º, II e §2º; art. 10, III. | F15: =IF(C15="Atende",8,IF(C15="Parcial",4,0)) -> 4 | G15: Parcial | H15: Há cláusulas genéricas de sigilo em códigos de ética ou normativos equivalentes | I15: Art. 9º, §4º. | J15: =IF(G15="Atende",7,IF(G15="Parcial",3.5,0)) -> 3.5 | K15: =SUM(F15,J15) -> 7.5 | L15: Doc. SEI 37070578
A16: GO | B16: Goiás | C16: Atende | D16: Procedimentos de sigilo reforçado, restrição de acesso e fluxos de emergência para esses casos;Protocolo para situações de risco à vida ou à integridade de pessoas privadas de liberdade;Protocolo para assédio moral ou sexual envolvendo servidores(as) penais;Protocolo para outras formas de violência institucional em unidades penais;Protocolo para corrupção e irregularidades graves na gestão dos serviços penais;Protocolo para ameaças, retaliações ou perseguições contra servidores(as) penais em razão de manifestações ou denúncias;Protocolo para casos de tortura ou tratamento cruel, desumano ou degradante em unidades penais; | E16: Art. 4º, II e §2º; art. 10, III. | F16: =IF(C16="Atende",8,IF(C16="Parcial",4,0)) -> 8 | G16: Atende | H16: Além do termo, há rotinas de reforço e capacitação periódica sobre sigilo e proteção de dados pessoais | I16: Art. 9º, §4º. | J16: =IF(G16="Atende",7,IF(G16="Parcial",3.5,0)) -> 7 | K16: =SUM(F16,J16) -> 15 | L16: Doc. SEI 37070578
A17: MA | B17: Maranhão | C17: Atende | D17: Protocolo para situações de risco à vida ou à integridade de pessoas privadas de liberdade;Protocolo para casos de tortura ou tratamento cruel, desumano ou degradante em unidades penais;Protocolo para outras formas de violência institucional em unidades penais;Protocolo para assédio moral ou sexual envolvendo servidores(as) penais;Procedimentos de sigilo reforçado, restrição de acesso e fluxos de emergência para esses casos; | E17: Art. 4º, II e §2º; art. 10, III. | F17: =IF(C17="Atende",8,IF(C17="Parcial",4,0)) -> 8 | G17: Atende | H17: Há cláusulas genéricas de sigilo em códigos de ética ou normativos equivalentes | I17: Art. 9º, §4º. | J17: =IF(G17="Atende",7,IF(G17="Parcial",3.5,0)) -> 7 | K17: =SUM(F17,J17) -> 15 | L17: Doc. SEI 37070578
A18: MT | B18: Mato Grosso | C18: Atende | D18: Procedimentos de sigilo reforçado, restrição de acesso e fluxos de emergência para esses casos;Protocolo para situações de risco à vida ou à integridade de pessoas privadas de liberdade;Protocolo para casos de tortura ou tratamento cruel, desumano ou degradante em unidades penais;Protocolo para outras formas de violência institucional em unidades penais;Protocolo para assédio moral ou sexual envolvendo servidores(as) penais;Protocolo para ameaças, retaliações ou perseguições contra servidores(as) penais em razão de manifestações ou denúncias;Protocolo para corrupção e irregularidades graves na gestão dos serviços penais; | E18: Art. 4º, II e §2º; art. 10, III. | F18: =IF(C18="Atende",8,IF(C18="Parcial",4,0)) -> 8 | G18: Atende | H18: Há cláusulas genéricas de sigilo em códigos de ética ou normativos equivalentes | I18: Art. 9º, §4º. | J18: =IF(G18="Atende",7,IF(G18="Parcial",3.5,0)) -> 7 | K18: =SUM(F18,J18) -> 15 | L18: Doc. SEI 37070578
... A34: TO | B34: Tocantins | C34: Sem evidência | D34: Procedimentos de sigilo reforçado, restrição de acesso e fluxos de emergência para esses casos;Protocolo para corrupção e irregularidades graves na gestão dos serviços penais;Protocolo para ameaças, retaliações ou perseguições contra servidores(as) penais em razão de manifestações ou denúncias;Protocolo para assédio moral ou sexual envolvendo servidores(as) penais;Protocolo para outras formas de violência institucional em unidades penais;Protocolo para casos de tortura ou tratamento cruel, desumano ou degradante em unidades penais;Protocolo para situações de risco à vida ou à integridade de pessoas privadas de liberdade; | E34: Art. 4º, II e §2º; art. 10, III. | F34: =IF(C34="Atende",8,IF(C34="Parcial",4,0)) -> 0 | G34: Sem evidência | H34: A equipe assina Termo de Compromisso de Manutenção de Sigilo Funcional específico para atuação na Ouvidoria de Serviços Penais | I34: Art. 9º, §4º. | J34: =IF(G34="Atende",7,IF(G34="Parcial",3.5,0)) -> 0 | K34: =SUM(F34,J34) -> 0 | L34: Doc. SEI 37070578

Sheet 04_Acessibilidade
A1: 04 — Acessibilidade e atendimento humanizado
A2: Peso da dimensão: 15 pontos. Cada pergunta do diagnóstico pertence exclusivamente a uma única dimensão da matriz.
A4: Identificação | C4: Item 1 — Canais institucionais acessíveis | O4: Item 2 — Condições de atendimento reservado e acessível | S4: Item 3 — Alcance dos públicos dos serviços penais | AA4: Resultado da dimensão
A5: UF | B5: Unidade Federativa | C5: M2-41 — E-mail institucional exclusivo | D5: Resposta do diagnóstico | E5: Fundamentação na IN nº 75/2026 | F5: 2 pts | G5: M2-43 — Linha telefônica funcional de uso restrito | H5: Resposta do diagnóstico | I5: Fundamentação na IN nº 75/2026 | J5: 2 pts | K5: M2-47 — Endereço postal próprio ou referência clara | L5: Resposta do diagnóstico | M5: Fundamentação na IN nº 75/2026 | N5: 2 pts | O5: M2-16 — Espaço físico da Ouvidoria | P5: Resposta do diagnóstico | Q5: Fundamentação na IN nº 75/2026 | R5: 3 pts | S5: M1-13 — Públicos atendidos no plano normativo | T5: Resposta do diagnóstico | U5: Fundamentação na IN nº 75/2026 | V5: 3 pts | W5: M4-64 — Públicos atendidos na prática | X5: Resposta do diagnóstico | Y5: Fundamentação na IN nº 75/2026 | Z5: 3 pts | AA5: Pontuação /15 | AB5: Evidências / observações
A6: Como aplicar / resposta / fundamento → | C6: 2 pts: possui e-mail institucional exclusivo ativo. 1 pt: e-mail institucional não exclusivo ou com limitação relevante. 0 pt: inexistente ou sem evidência. | D6: Resposta original consolidada do diagnóstico das Ouvidorias Estaduais de Serviços Penais. | E6: Art. 7º, §2º, I. | F6: 2 = atende 1 = parcial 0 = não atende / sem evidência | G6: 2 pts: possui telefone/ramal funcional de uso restrito. 1 pt: telefone compartilhado ou limitado. 0 pt: inexistente ou sem evidência. | H6: Resposta original consolidada do diagnóstico das Ouvidorias Estaduais de Serviços Penais. | I6: Art. 7º, §2º, II. | J6: 2 = atende 1 = parcial 0 = não atende / sem evidência | K6: 2 pts: existe endereço postal próprio ou referência institucional clara. 1 pt: referência indireta/compartilhada que ainda permite recebimento. 0 pt: inexistente ou sem evidência. | L6: Resposta original consolidada do diagnóstico das Ouvidorias Estaduais de Serviços Penais. | M6: Art. 7º, §2º, IV. | N6: 2 = atende 1 = parcial 0 = não atende / sem evidência | O6: 3 pts: espaço com privacidade, confidencialidade e condições de acessibilidade/atendimento. 1,5 pt: espaço existente com limitações relevantes. 0 pt: sem espaço adequado ou sem evidência. | P6: Resposta original consolidada do diagnóstico das Ouvidorias Estaduais de Serviços Penais. | Q6: Art. 7º, §1º, I e II. | R6: 3 = atende 1.5 = parcial 0 = não atende / sem evidência | S6: 3 pts: previsão normativa contempla amplamente os públicos dos serviços penais. 1,5 pt: contempla apenas parte relevante dos públicos. 0 pt: previsão restrita/inexistente ou sem evidência. | T6: Resposta original consolidada do diagnóstico das Ouvidorias Estaduais de Serviços Penais. | U6: Art. 4º, III; art. 10, I. | V6: 3 = atende 1.5 = parcial 0 = não atende / sem evidência | W6: 3 pts: atendimento alcança de forma ampla os principais públicos dos serviços penais. 1,5 pt: alcance parcial ou com barreiras relevantes. 0 pt: alcance muito restrito ou sem evidência. | X6: Resposta original consolidada do diagnóstico das Ouvidorias Estaduais de Serviços Penais. | Y6: Art. 4º, III; art. 10, I. | Z6: 3 = atende 1.5 = parcial 0 = não atende / sem evidência | AA6: Soma automática das perguntas desta dimensão. | AB6: Referência documental geral das respostas: Doc. SEI 37070578.
A7: AC | B7: Acre | C7: Atende | D7: Sim | E7: Art. 7º, §2º, I. | F7: =IF(C7="Atende",2,IF(C7="Parcial",1,0)) -> 2 | G7: Não atende | H7: Não | I7: Art. 7º, §2º, II. | J7: =IF(G7="Atende",2,IF(G7="Parcial",1,0)) -> 0 | K7: Atende | L7: Sim | M7: Art. 7º, §2º, IV. | N7: =IF(K7="Atende",2,IF(K7="Parcial",1,0)) -> 2 | O7: Atende | P7: Possui instalação física própria, com privacidade, acessibilidade e condições adequadas de atendimento | Q7: Art. 7º, §1º, I e II. | R7: =IF(O7="Atende",3,IF(O7="Parcial",1.5,0)) -> 3 | S7: Atende | T7: Pessoas privadas de liberdade;Familiares / pessoas de referência de pessoas privadas de liberdade;Servidores(as) penais e demais trabalhadores(as) dos serviços penais;Demais cidadãos e usuários de serviços relacionados ao sistema penal; | U7: Art. 4º, III; art. 10, I. | V7: =IF(S7="Atende",3,IF(S7="Parcial",1.5,0)) -> 3 | W7: Atende | X7: Pessoas privadas de liberdade: Nunca recebe manifestações desse público | Familiares / pessoas de referência de pessoas privadas de liberdade: Recebe com alta frequência | Servidores(as) penais e demais trabalhadores(as) dos serviços penais: Recebe com alguma frequência | Outros cidadãos e usuários de serviços relacionados ao sistema penal: Recebe com alguma frequência | Y7: Art. 4º, III; art. 10, I. | Z7: =IF(W7="Atende",3,IF(W7="Parcial",1.5,0)) -> 3 | AA7: =SUM(F7,J7,N7,R7,V7,Z7) -> 13 | AB7: Doc. SEI 37070578
